INFO 2025-06-27 17:38:00,794 autoreload 70325 8723368000 Watching for file changes with StatReloader
ERROR 2025-06-27 17:38:15,157 log 70325 6196883456 Internal Server Error: /api/orders
Traceback (most recent call last):
  File "/Users/mahesh/Desktop/PythonProject/aquaticexotica_backend/.venv/lib/python3.13/site-packages/django/db/backends/utils.py", line 105, in _execute
    return self.cursor.execute(sql, params)
           ~~~~~~~~~~~~~~~~~~~^^^^^^^^^^^^^
psycopg2.errors.NotNullViolation: null value in column "total_amount" of relation "core_order" violates not-null constraint
DETAIL:  Failing row contains (3, null, 150.00, pending, 2025-06-27 17:38:15.077719+00, 2025-06-27 17:38:15.077771+00, 7, 1).


The above exception was the direct cause of the following exception:

Traceback (most recent call last):
  File "/Users/mahesh/Desktop/PythonProject/aquaticexotica_backend/.venv/lib/python3.13/site-packages/django/core/handlers/exception.py", line 55, in inner
    response = get_response(request)
  File "/Users/mahesh/Desktop/PythonProject/aquaticexotica_backend/.venv/lib/python3.13/site-packages/django/core/handlers/base.py", line 197, in _get_response
    response = wrapped_callback(request, *callback_args, **callback_kwargs)
  File "/Users/mahesh/Desktop/PythonProject/aquaticexotica_backend/.venv/lib/python3.13/site-packages/django/views/decorators/csrf.py", line 65, in _view_wrapper
    return view_func(request, *args, **kwargs)
  File "/Users/mahesh/Desktop/PythonProject/aquaticexotica_backend/.venv/lib/python3.13/site-packages/rest_framework/viewsets.py", line 125, in view
    return self.dispatch(request, *args, **kwargs)
           ~~~~~~~~~~~~~^^^^^^^^^^^^^^^^^^^^^^^^^^
  File "/Users/mahesh/Desktop/PythonProject/aquaticexotica_backend/.venv/lib/python3.13/site-packages/rest_framework/views.py", line 515, in dispatch
    response = self.handle_exception(exc)
  File "/Users/mahesh/Desktop/PythonProject/aquaticexotica_backend/.venv/lib/python3.13/site-packages/rest_framework/views.py", line 475, in handle_exception
    self.raise_uncaught_exception(exc)
    ~~~~~~~~~~~~~~~~~~~~~~~~~~~~~^^^^^
  File "/Users/mahesh/Desktop/PythonProject/aquaticexotica_backend/.venv/lib/python3.13/site-packages/rest_framework/views.py", line 486, in raise_uncaught_exception
    raise exc
  File "/Users/mahesh/Desktop/PythonProject/aquaticexotica_backend/.venv/lib/python3.13/site-packages/rest_framework/views.py", line 512, in dispatch
    response = handler(request, *args, **kwargs)
  File "/Users/mahesh/Desktop/PythonProject/aquaticexotica_backend/.venv/lib/python3.13/site-packages/rest_framework/mixins.py", line 19, in create
    self.perform_create(serializer)
    ~~~~~~~~~~~~~~~~~~~^^^^^^^^^^^^
  File "/Users/mahesh/Desktop/PythonProject/aquaticexotica_backend/.venv/lib/python3.13/site-packages/rest_framework/mixins.py", line 24, in perform_create
    serializer.save()
    ~~~~~~~~~~~~~~~^^
  File "/Users/mahesh/Desktop/PythonProject/aquaticexotica_backend/.venv/lib/python3.13/site-packages/rest_framework/serializers.py", line 210, in save
    self.instance = self.create(validated_data)
                    ~~~~~~~~~~~^^^^^^^^^^^^^^^^
  File "/Users/mahesh/Desktop/PythonProject/aquaticexotica_backend/core/serializers.py", line 218, in create
    order = Order.objects.create(
        user=user,
        shipping_address=shipping_address,
        shipping_cost=shipping_cost
    )
  File "/Users/mahesh/Desktop/PythonProject/aquaticexotica_backend/.venv/lib/python3.13/site-packages/django/db/models/manager.py", line 87, in manager_method
    return getattr(self.get_queryset(), name)(*args, **kwargs)
           ~~~~~~~~~~~~~~~~~~~~~~~~~~~~~~~~~~^^^^^^^^^^^^^^^^^
  File "/Users/mahesh/Desktop/PythonProject/aquaticexotica_backend/.venv/lib/python3.13/site-packages/django/db/models/query.py", line 663, in create
    obj.save(force_insert=True, using=self.db)
    ~~~~~~~~^^^^^^^^^^^^^^^^^^^^^^^^^^^^^^^^^^
  File "/Users/mahesh/Desktop/PythonProject/aquaticexotica_backend/.venv/lib/python3.13/site-packages/django/db/models/base.py", line 902, in save
    self.save_base(
    ~~~~~~~~~~~~~~^
        using=using,
        ^^^^^^^^^^^^
    ...<2 lines>...
        update_fields=update_fields,
        ^^^^^^^^^^^^^^^^^^^^^^^^^^^^
    )
    ^
  File "/Users/mahesh/Desktop/PythonProject/aquaticexotica_backend/.venv/lib/python3.13/site-packages/django/db/models/base.py", line 1008, in save_base
    updated = self._save_table(
        raw,
    ...<4 lines>...
        update_fields,
    )
  File "/Users/mahesh/Desktop/PythonProject/aquaticexotica_backend/.venv/lib/python3.13/site-packages/django/db/models/base.py", line 1169, in _save_table
    results = self._do_insert(
        cls._base_manager, using, fields, returning_fields, raw
    )
  File "/Users/mahesh/Desktop/PythonProject/aquaticexotica_backend/.venv/lib/python3.13/site-packages/django/db/models/base.py", line 1210, in _do_insert
    return manager._insert(
           ~~~~~~~~~~~~~~~^
        [self],
        ^^^^^^^
    ...<3 lines>...
        raw=raw,
        ^^^^^^^^
    )
    ^
  File "/Users/mahesh/Desktop/PythonProject/aquaticexotica_backend/.venv/lib/python3.13/site-packages/django/db/models/manager.py", line 87, in manager_method
    return getattr(self.get_queryset(), name)(*args, **kwargs)
           ~~~~~~~~~~~~~~~~~~~~~~~~~~~~~~~~~~^^^^^^^^^^^^^^^^^
  File "/Users/mahesh/Desktop/PythonProject/aquaticexotica_backend/.venv/lib/python3.13/site-packages/django/db/models/query.py", line 1868, in _insert
    return query.get_compiler(using=using).execute_sql(returning_fields)
           ~~~~~~~~~~~~~~~~~~~~~~~~~~~~~~~~~~~~~~~~~~~^^^^^^^^^^^^^^^^^^
  File "/Users/mahesh/Desktop/PythonProject/aquaticexotica_backend/.venv/lib/python3.13/site-packages/django/db/models/sql/compiler.py", line 1882, in execute_sql
    cursor.execute(sql, params)
    ~~~~~~~~~~~~~~^^^^^^^^^^^^^
  File "/Users/mahesh/Desktop/PythonProject/aquaticexotica_backend/.venv/lib/python3.13/site-packages/django/db/backends/utils.py", line 79, in execute
    return self._execute_with_wrappers(
           ~~~~~~~~~~~~~~~~~~~~~~~~~~~^
        sql, params, many=False, executor=self._execute
        ^^^^^^^^^^^^^^^^^^^^^^^^^^^^^^^^^^^^^^^^^^^^^^^
    )
    ^
  File "/Users/mahesh/Desktop/PythonProject/aquaticexotica_backend/.venv/lib/python3.13/site-packages/django/db/backends/utils.py", line 92, in _execute_with_wrappers
    return executor(sql, params, many, context)
  File "/Users/mahesh/Desktop/PythonProject/aquaticexotica_backend/.venv/lib/python3.13/site-packages/django/db/backends/utils.py", line 100, in _execute
    with self.db.wrap_database_errors:
         ^^^^^^^^^^^^^^^^^^^^^^^^^^^^
  File "/Users/mahesh/Desktop/PythonProject/aquaticexotica_backend/.venv/lib/python3.13/site-packages/django/db/utils.py", line 91, in __exit__
    raise dj_exc_value.with_traceback(traceback) from exc_value
  File "/Users/mahesh/Desktop/PythonProject/aquaticexotica_backend/.venv/lib/python3.13/site-packages/django/db/backends/utils.py", line 105, in _execute
    return self.cursor.execute(sql, params)
           ~~~~~~~~~~~~~~~~~~~^^^^^^^^^^^^^
django.db.utils.IntegrityError: null value in column "total_amount" of relation "core_order" violates not-null constraint
DETAIL:  Failing row contains (3, null, 150.00, pending, 2025-06-27 17:38:15.077719+00, 2025-06-27 17:38:15.077771+00, 7, 1).

INFO 2025-06-27 17:40:19,725 autoreload 70325 8723368000 /Users/mahesh/Desktop/PythonProject/aquaticexotica_backend/core/serializers.py changed, reloading.
INFO 2025-06-27 17:40:20,042 autoreload 70372 8723368000 Watching for file changes with StatReloader
INFO 2025-06-27 17:41:52,705 autoreload 70372 8723368000 /Users/mahesh/Desktop/PythonProject/aquaticexotica_backend/core/serializers.py changed, reloading.
INFO 2025-06-27 17:41:52,989 autoreload 70416 8723368000 Watching for file changes with StatReloader
ERROR 2025-06-27 17:42:01,114 log 70416 6203994112 Internal Server Error: /api/orders
Traceback (most recent call last):
  File "/Users/mahesh/Desktop/PythonProject/aquaticexotica_backend/.venv/lib/python3.13/site-packages/django/core/handlers/exception.py", line 55, in inner
    response = get_response(request)
  File "/Users/mahesh/Desktop/PythonProject/aquaticexotica_backend/.venv/lib/python3.13/site-packages/django/core/handlers/base.py", line 197, in _get_response
    response = wrapped_callback(request, *callback_args, **callback_kwargs)
  File "/Users/mahesh/Desktop/PythonProject/aquaticexotica_backend/.venv/lib/python3.13/site-packages/django/views/decorators/csrf.py", line 65, in _view_wrapper
    return view_func(request, *args, **kwargs)
  File "/Users/mahesh/Desktop/PythonProject/aquaticexotica_backend/.venv/lib/python3.13/site-packages/rest_framework/viewsets.py", line 125, in view
    return self.dispatch(request, *args, **kwargs)
           ~~~~~~~~~~~~~^^^^^^^^^^^^^^^^^^^^^^^^^^
  File "/Users/mahesh/Desktop/PythonProject/aquaticexotica_backend/.venv/lib/python3.13/site-packages/rest_framework/views.py", line 515, in dispatch
    response = self.handle_exception(exc)
  File "/Users/mahesh/Desktop/PythonProject/aquaticexotica_backend/.venv/lib/python3.13/site-packages/rest_framework/views.py", line 475, in handle_exception
    self.raise_uncaught_exception(exc)
    ~~~~~~~~~~~~~~~~~~~~~~~~~~~~~^^^^^
  File "/Users/mahesh/Desktop/PythonProject/aquaticexotica_backend/.venv/lib/python3.13/site-packages/rest_framework/views.py", line 486, in raise_uncaught_exception
    raise exc
  File "/Users/mahesh/Desktop/PythonProject/aquaticexotica_backend/.venv/lib/python3.13/site-packages/rest_framework/views.py", line 512, in dispatch
    response = handler(request, *args, **kwargs)
  File "/Users/mahesh/Desktop/PythonProject/aquaticexotica_backend/.venv/lib/python3.13/site-packages/rest_framework/mixins.py", line 19, in create
    self.perform_create(serializer)
    ~~~~~~~~~~~~~~~~~~~^^^^^^^^^^^^
  File "/Users/mahesh/Desktop/PythonProject/aquaticexotica_backend/.venv/lib/python3.13/site-packages/rest_framework/mixins.py", line 24, in perform_create
    serializer.save()
    ~~~~~~~~~~~~~~~^^
  File "/Users/mahesh/Desktop/PythonProject/aquaticexotica_backend/.venv/lib/python3.13/site-packages/rest_framework/serializers.py", line 210, in save
    self.instance = self.create(validated_data)
                    ~~~~~~~~~~~^^^^^^^^^^^^^^^^
  File "/Users/mahesh/Desktop/PythonProject/aquaticexotica_backend/core/serializers.py", line 227, in create
    product_id = item["product_id"]
                 ~~~~^^^^^^^^^^^^^^
KeyError: 'product_id'
ERROR 2025-06-27 17:42:45,599 log 70416 6203994112 Internal Server Error: /api/orders
Traceback (most recent call last):
  File "/Users/mahesh/Desktop/PythonProject/aquaticexotica_backend/.venv/lib/python3.13/site-packages/django/core/handlers/exception.py", line 55, in inner
    response = get_response(request)
  File "/Users/mahesh/Desktop/PythonProject/aquaticexotica_backend/.venv/lib/python3.13/site-packages/django/core/handlers/base.py", line 197, in _get_response
    response = wrapped_callback(request, *callback_args, **callback_kwargs)
  File "/Users/mahesh/Desktop/PythonProject/aquaticexotica_backend/.venv/lib/python3.13/site-packages/django/views/decorators/csrf.py", line 65, in _view_wrapper
    return view_func(request, *args, **kwargs)
  File "/Users/mahesh/Desktop/PythonProject/aquaticexotica_backend/.venv/lib/python3.13/site-packages/rest_framework/viewsets.py", line 125, in view
    return self.dispatch(request, *args, **kwargs)
           ~~~~~~~~~~~~~^^^^^^^^^^^^^^^^^^^^^^^^^^
  File "/Users/mahesh/Desktop/PythonProject/aquaticexotica_backend/.venv/lib/python3.13/site-packages/rest_framework/views.py", line 515, in dispatch
    response = self.handle_exception(exc)
  File "/Users/mahesh/Desktop/PythonProject/aquaticexotica_backend/.venv/lib/python3.13/site-packages/rest_framework/views.py", line 475, in handle_exception
    self.raise_uncaught_exception(exc)
    ~~~~~~~~~~~~~~~~~~~~~~~~~~~~~^^^^^
  File "/Users/mahesh/Desktop/PythonProject/aquaticexotica_backend/.venv/lib/python3.13/site-packages/rest_framework/views.py", line 486, in raise_uncaught_exception
    raise exc
  File "/Users/mahesh/Desktop/PythonProject/aquaticexotica_backend/.venv/lib/python3.13/site-packages/rest_framework/views.py", line 512, in dispatch
    response = handler(request, *args, **kwargs)
  File "/Users/mahesh/Desktop/PythonProject/aquaticexotica_backend/.venv/lib/python3.13/site-packages/rest_framework/mixins.py", line 19, in create
    self.perform_create(serializer)
    ~~~~~~~~~~~~~~~~~~~^^^^^^^^^^^^
  File "/Users/mahesh/Desktop/PythonProject/aquaticexotica_backend/.venv/lib/python3.13/site-packages/rest_framework/mixins.py", line 24, in perform_create
    serializer.save()
    ~~~~~~~~~~~~~~~^^
  File "/Users/mahesh/Desktop/PythonProject/aquaticexotica_backend/.venv/lib/python3.13/site-packages/rest_framework/serializers.py", line 210, in save
    self.instance = self.create(validated_data)
                    ~~~~~~~~~~~^^^^^^^^^^^^^^^^
  File "/Users/mahesh/Desktop/PythonProject/aquaticexotica_backend/core/serializers.py", line 227, in create
    product_id = item["product_id"]
                 ~~~~^^^^^^^^^^^^^^
KeyError: 'product_id'
INFO 2025-06-27 17:43:05,252 autoreload 70416 8723368000 /Users/mahesh/Desktop/PythonProject/aquaticexotica_backend/core/serializers.py changed, reloading.
INFO 2025-06-27 17:43:05,522 autoreload 70436 8723368000 Watching for file changes with StatReloader
ERROR 2025-06-27 17:43:08,969 log 70436 6194081792 Internal Server Error: /api/orders
Traceback (most recent call last):
  File "/Users/mahesh/Desktop/PythonProject/aquaticexotica_backend/.venv/lib/python3.13/site-packages/django/core/handlers/exception.py", line 55, in inner
    response = get_response(request)
  File "/Users/mahesh/Desktop/PythonProject/aquaticexotica_backend/.venv/lib/python3.13/site-packages/django/core/handlers/base.py", line 197, in _get_response
    response = wrapped_callback(request, *callback_args, **callback_kwargs)
  File "/Users/mahesh/Desktop/PythonProject/aquaticexotica_backend/.venv/lib/python3.13/site-packages/django/views/decorators/csrf.py", line 65, in _view_wrapper
    return view_func(request, *args, **kwargs)
  File "/Users/mahesh/Desktop/PythonProject/aquaticexotica_backend/.venv/lib/python3.13/site-packages/rest_framework/viewsets.py", line 125, in view
    return self.dispatch(request, *args, **kwargs)
           ~~~~~~~~~~~~~^^^^^^^^^^^^^^^^^^^^^^^^^^
  File "/Users/mahesh/Desktop/PythonProject/aquaticexotica_backend/.venv/lib/python3.13/site-packages/rest_framework/views.py", line 515, in dispatch
    response = self.handle_exception(exc)
  File "/Users/mahesh/Desktop/PythonProject/aquaticexotica_backend/.venv/lib/python3.13/site-packages/rest_framework/views.py", line 475, in handle_exception
    self.raise_uncaught_exception(exc)
    ~~~~~~~~~~~~~~~~~~~~~~~~~~~~~^^^^^
  File "/Users/mahesh/Desktop/PythonProject/aquaticexotica_backend/.venv/lib/python3.13/site-packages/rest_framework/views.py", line 486, in raise_uncaught_exception
    raise exc
  File "/Users/mahesh/Desktop/PythonProject/aquaticexotica_backend/.venv/lib/python3.13/site-packages/rest_framework/views.py", line 512, in dispatch
    response = handler(request, *args, **kwargs)
  File "/Users/mahesh/Desktop/PythonProject/aquaticexotica_backend/.venv/lib/python3.13/site-packages/rest_framework/mixins.py", line 19, in create
    self.perform_create(serializer)
    ~~~~~~~~~~~~~~~~~~~^^^^^^^^^^^^
  File "/Users/mahesh/Desktop/PythonProject/aquaticexotica_backend/.venv/lib/python3.13/site-packages/rest_framework/mixins.py", line 24, in perform_create
    serializer.save()
    ~~~~~~~~~~~~~~~^^
  File "/Users/mahesh/Desktop/PythonProject/aquaticexotica_backend/.venv/lib/python3.13/site-packages/rest_framework/serializers.py", line 210, in save
    self.instance = self.create(validated_data)
                    ~~~~~~~~~~~^^^^^^^^^^^^^^^^
  File "/Users/mahesh/Desktop/PythonProject/aquaticexotica_backend/core/serializers.py", line 228, in create
    product_id = item["product_id"]
                 ~~~~^^^^^^^^^^^^^^
KeyError: 'product_id'
INFO 2025-06-27 17:44:17,769 autoreload 70436 8723368000 /Users/mahesh/Desktop/PythonProject/aquaticexotica_backend/core/serializers.py changed, reloading.
INFO 2025-06-27 17:44:18,066 autoreload 70465 8723368000 Watching for file changes with StatReloader
INFO 2025-06-27 18:41:59,042 autoreload 70465 8723368000 /Users/mahesh/Desktop/PythonProject/aquaticexotica_backend/core/serializers.py changed, reloading.
INFO 2025-06-27 18:41:59,362 autoreload 71115 8723368000 Watching for file changes with StatReloader
ERROR 2025-06-27 18:42:13,986 log 71115 6195212288 Internal Server Error: /api/orders
Traceback (most recent call last):
  File "/Users/mahesh/Desktop/PythonProject/aquaticexotica_backend/.venv/lib/python3.13/site-packages/django/db/models/fields/__init__.py", line 2128, in get_prep_value
    return int(value)
TypeError: int() argument must be a string, a bytes-like object or a real number, not 'Product'

The above exception was the direct cause of the following exception:

Traceback (most recent call last):
  File "/Users/mahesh/Desktop/PythonProject/aquaticexotica_backend/.venv/lib/python3.13/site-packages/django/core/handlers/exception.py", line 55, in inner
    response = get_response(request)
  File "/Users/mahesh/Desktop/PythonProject/aquaticexotica_backend/.venv/lib/python3.13/site-packages/django/core/handlers/base.py", line 197, in _get_response
    response = wrapped_callback(request, *callback_args, **callback_kwargs)
  File "/Users/mahesh/Desktop/PythonProject/aquaticexotica_backend/.venv/lib/python3.13/site-packages/django/views/decorators/csrf.py", line 65, in _view_wrapper
    return view_func(request, *args, **kwargs)
  File "/Users/mahesh/Desktop/PythonProject/aquaticexotica_backend/.venv/lib/python3.13/site-packages/rest_framework/viewsets.py", line 125, in view
    return self.dispatch(request, *args, **kwargs)
           ~~~~~~~~~~~~~^^^^^^^^^^^^^^^^^^^^^^^^^^
  File "/Users/mahesh/Desktop/PythonProject/aquaticexotica_backend/.venv/lib/python3.13/site-packages/rest_framework/views.py", line 515, in dispatch
    response = self.handle_exception(exc)
  File "/Users/mahesh/Desktop/PythonProject/aquaticexotica_backend/.venv/lib/python3.13/site-packages/rest_framework/views.py", line 475, in handle_exception
    self.raise_uncaught_exception(exc)
    ~~~~~~~~~~~~~~~~~~~~~~~~~~~~~^^^^^
  File "/Users/mahesh/Desktop/PythonProject/aquaticexotica_backend/.venv/lib/python3.13/site-packages/rest_framework/views.py", line 486, in raise_uncaught_exception
    raise exc
  File "/Users/mahesh/Desktop/PythonProject/aquaticexotica_backend/.venv/lib/python3.13/site-packages/rest_framework/views.py", line 512, in dispatch
    response = handler(request, *args, **kwargs)
  File "/Users/mahesh/Desktop/PythonProject/aquaticexotica_backend/.venv/lib/python3.13/site-packages/rest_framework/mixins.py", line 19, in create
    self.perform_create(serializer)
    ~~~~~~~~~~~~~~~~~~~^^^^^^^^^^^^
  File "/Users/mahesh/Desktop/PythonProject/aquaticexotica_backend/.venv/lib/python3.13/site-packages/rest_framework/mixins.py", line 24, in perform_create
    serializer.save()
    ~~~~~~~~~~~~~~~^^
  File "/Users/mahesh/Desktop/PythonProject/aquaticexotica_backend/.venv/lib/python3.13/site-packages/rest_framework/serializers.py", line 210, in save
    self.instance = self.create(validated_data)
                    ~~~~~~~~~~~^^^^^^^^^^^^^^^^
  File "/Users/mahesh/Desktop/PythonProject/aquaticexotica_backend/core/serializers.py", line 237, in create
    OrderItem.objects.create(
    ~~~~~~~~~~~~~~~~~~~~~~~~^
        order=order,
        ^^^^^^^^^^^^
    ...<2 lines>...
        price=price
        ^^^^^^^^^^^
    )
    ^
  File "/Users/mahesh/Desktop/PythonProject/aquaticexotica_backend/.venv/lib/python3.13/site-packages/django/db/models/manager.py", line 87, in manager_method
    return getattr(self.get_queryset(), name)(*args, **kwargs)
           ~~~~~~~~~~~~~~~~~~~~~~~~~~~~~~~~~~^^^^^^^^^^^^^^^^^
  File "/Users/mahesh/Desktop/PythonProject/aquaticexotica_backend/.venv/lib/python3.13/site-packages/django/db/models/query.py", line 663, in create
    obj.save(force_insert=True, using=self.db)
    ~~~~~~~~^^^^^^^^^^^^^^^^^^^^^^^^^^^^^^^^^^
  File "/Users/mahesh/Desktop/PythonProject/aquaticexotica_backend/.venv/lib/python3.13/site-packages/django/db/models/base.py", line 902, in save
    self.save_base(
    ~~~~~~~~~~~~~~^
        using=using,
        ^^^^^^^^^^^^
    ...<2 lines>...
        update_fields=update_fields,
        ^^^^^^^^^^^^^^^^^^^^^^^^^^^^
    )
    ^
  File "/Users/mahesh/Desktop/PythonProject/aquaticexotica_backend/.venv/lib/python3.13/site-packages/django/db/models/base.py", line 1008, in save_base
    updated = self._save_table(
        raw,
    ...<4 lines>...
        update_fields,
    )
  File "/Users/mahesh/Desktop/PythonProject/aquaticexotica_backend/.venv/lib/python3.13/site-packages/django/db/models/base.py", line 1169, in _save_table
    results = self._do_insert(
        cls._base_manager, using, fields, returning_fields, raw
    )
  File "/Users/mahesh/Desktop/PythonProject/aquaticexotica_backend/.venv/lib/python3.13/site-packages/django/db/models/base.py", line 1210, in _do_insert
    return manager._insert(
           ~~~~~~~~~~~~~~~^
        [self],
        ^^^^^^^
    ...<3 lines>...
        raw=raw,
        ^^^^^^^^
    )
    ^
  File "/Users/mahesh/Desktop/PythonProject/aquaticexotica_backend/.venv/lib/python3.13/site-packages/django/db/models/manager.py", line 87, in manager_method
    return getattr(self.get_queryset(), name)(*args, **kwargs)
           ~~~~~~~~~~~~~~~~~~~~~~~~~~~~~~~~~~^^^^^^^^^^^^^^^^^
  File "/Users/mahesh/Desktop/PythonProject/aquaticexotica_backend/.venv/lib/python3.13/site-packages/django/db/models/query.py", line 1868, in _insert
    return query.get_compiler(using=using).execute_sql(returning_fields)
           ~~~~~~~~~~~~~~~~~~~~~~~~~~~~~~~~~~~~~~~~~~~^^^^^^^^^^^^^^^^^^
  File "/Users/mahesh/Desktop/PythonProject/aquaticexotica_backend/.venv/lib/python3.13/site-packages/django/db/models/sql/compiler.py", line 1881, in execute_sql
    for sql, params in self.as_sql():
                       ~~~~~~~~~~~^^
  File "/Users/mahesh/Desktop/PythonProject/aquaticexotica_backend/.venv/lib/python3.13/site-packages/django/db/models/sql/compiler.py", line 1806, in as_sql
    self.prepare_value(field, self.pre_save_val(field, obj))
    ~~~~~~~~~~~~~~~~~~^^^^^^^^^^^^^^^^^^^^^^^^^^^^^^^^^^^^^^
  File "/Users/mahesh/Desktop/PythonProject/aquaticexotica_backend/.venv/lib/python3.13/site-packages/django/db/models/sql/compiler.py", line 1741, in prepare_value
    return field.get_db_prep_save(value, connection=self.connection)
           ~~~~~~~~~~~~~~~~~~~~~~^^^^^^^^^^^^^^^^^^^^^^^^^^^^^^^^^^^
  File "/Users/mahesh/Desktop/PythonProject/aquaticexotica_backend/.venv/lib/python3.13/site-packages/django/db/models/fields/related.py", line 1189, in get_db_prep_save
    return self.target_field.get_db_prep_save(value, connection=connection)
           ~~~~~~~~~~~~~~~~~~~~~~~~~~~~~~~~~~^^^^^^^^^^^^^^^^^^^^^^^^^^^^^^
  File "/Users/mahesh/Desktop/PythonProject/aquaticexotica_backend/.venv/lib/python3.13/site-packages/django/db/models/fields/__init__.py", line 1012, in get_db_prep_save
    return self.get_db_prep_value(value, connection=connection, prepared=False)
           ~~~~~~~~~~~~~~~~~~~~~~^^^^^^^^^^^^^^^^^^^^^^^^^^^^^^^^^^^^^^^^^^^^^^
  File "/Users/mahesh/Desktop/PythonProject/aquaticexotica_backend/.venv/lib/python3.13/site-packages/django/db/models/fields/__init__.py", line 2820, in get_db_prep_value
    value = self.get_prep_value(value)
  File "/Users/mahesh/Desktop/PythonProject/aquaticexotica_backend/.venv/lib/python3.13/site-packages/django/db/models/fields/__init__.py", line 2130, in get_prep_value
    raise e.__class__(
        "Field '%s' expected a number but got %r." % (self.name, value),
    ) from e
TypeError: Field 'id' expected a number but got <Product: Bucephalandra>.
INFO 2025-06-27 18:43:40,717 autoreload 71115 8723368000 /Users/mahesh/Desktop/PythonProject/aquaticexotica_backend/core/serializers.py changed, reloading.
INFO 2025-06-27 18:43:41,033 autoreload 71135 8723368000 Watching for file changes with StatReloader
INFO 2025-06-27 18:43:49,365 autoreload 71135 8723368000 /Users/mahesh/Desktop/PythonProject/aquaticexotica_backend/core/serializers.py changed, reloading.
INFO 2025-06-27 18:43:49,611 autoreload 71147 8723368000 Watching for file changes with StatReloader
